<?xml version="1.0" ?>
<robot name="three_segment_arm">
  <!-- base (seg0) -->
  <link name="base_link">
    <visual>
      <origin xyz="0.125 0 0" rpy="0 0 0"/>
      <geometry>
        <box size="0.25 0.04 0.03"/>
      </geometry>
      <material name="gray"><color rgba="0.6 0.6 0.6 1"/></material>
    </visual>
    <inertial>
      <origin xyz="0.125 0 0" rpy="0 0 0"/>
      <mass value="0.0"/>
      <inertia ixx="0.0" ixy="0.0" ixz="0.0" iyy="0.0" iyz="0.0" izz="0.0"/>
    </inertial>
  </link>

  <!-- seg1 -->
  <link name="link1">
    <visual>
      <origin xyz="0.125 0 0" rpy="0 0 0"/>
      <geometry>
        <box size="0.25 0.04 0.03"/>
      </geometry>
      <material name="blue"><color rgba="0.2 0.4 1 1"/></material>
    </visual>
    <inertial>
      <origin xyz="0.125 0 0"/>
      <mass value="0.5"/>
      <inertia ixx="0.001" ixy="0.0" ixz="0.0" iyy="0.001" iyz="0.0" izz="0.001"/>
    </inertial>
  </link>

  <!-- seg2 -->
  <link name="link2">
    <visual>
      <origin xyz="0.125 0 0" rpy="0 0 0"/>
      <geometry>
        <box size="0.25 0.4 0.03"/>
      </geometry>
      <material name="green"><color rgba="0.2 1 0.2 1"/></material>
    </visual>
    <inertial>
      <origin xyz="0.125 0 0"/>
      <mass value="0.4"/>
      <inertia ixx="0.0008" ixy="0.0" ixz="0.0" iyy="0.0008" iyz="0.0" izz="0.0008"/>
    </inertial>
  </link>

  <!-- joint between base and link1 at x = L0 -->
  <joint name="joint1" type="revolute">
    <parent link="base_link"/>
    <child link="link1"/>
    <origin xyz="0.25 0 0" rpy="0 0 0"/>
    <axis xyz="0 0 1"/>
    <limit effort="10.0" lower="-1.57079632679" upper="1.57079632679" velocity="5.0"/>
  </joint>

  <!-- joint between link1 and link2 at x = L0 + L1 -->
  <joint name="joint2" type="revolute">
    <parent link="link1"/>
    <child link="link2"/>
    <origin xyz="0.25 0 0" rpy="0 0 0"/>
    <axis xyz="0 1 0"/>
    <limit effort="10.0" lower="-1.57079632679" upper="1.57079632679" velocity="5.0"/>
  </joint>
</robot>
